Workbook

Sheet PageBinder at a glance
A1: PageBinder at a glance
A2: Quick reference drawn from the Comparison sheet by formula: each list below updates if a cell there changes. It shows where PageBinder differs from the other eleven programs, in both directions, and what everyone shares. It is not a ranking.
D3: PageBinder's answer
A4: Only PageBinder has these | D4: =COUNTIF(Comparison!$O$5:$O$72,"Only PageBinder") -> 4
A5: =IFERROR(INDEX(Comparison!$A$5:$A$72,MATCH(1,Comparison!$R$5:$R$72,0)),"") -> Saved emails show sender, subject, and date and are searchable | D5: =IFERROR(INDEX(Comparison!$B$5:$B$72,MATCH(1,Comparison!$R$5:$R$72,0)),"") -> Yes: .eml and .msg files
A6: =IFERROR(INDEX(Comparison!$A$5:$A$72,MATCH(2,Comparison!$R$5:$R$72,0)),"") -> Print preview | D6: =IFERROR(INDEX(Comparison!$B$5:$B$72,MATCH(2,Comparison!$R$5:$R$72,0)),"") -> Yes
A7: =IFERROR(INDEX(Comparison!$A$5:$A$72,MATCH(3,Comparison!$R$5:$R$72,0)),"") -> Detects a damaged page and restores the last good version automatically | D7: =IFERROR(INDEX(Comparison!$B$5:$B$72,MATCH(3,Comparison!$R$5:$R$72,0)),"") -> Yes: every page is checksummed and checked on open
A8: =IFERROR(INDEX(Comparison!$A$5:$A$72,MATCH(4,Comparison!$R$5:$R$72,0)),"") -> Verify-and-repair tool for a whole notebook | D8: =IFERROR(INDEX(Comparison!$B$5:$B$72,MATCH(4,Comparison!$R$5:$R$72,0)),"") -> Yes
A9: =IFERROR(INDEX(Comparison!$A$5:$A$72,MATCH(5,Comparison!$R$5:$R$72,0)),"") | D9: =IFERROR(INDEX(Comparison!$B$5:$B$72,MATCH(5,Comparison!$R$5:$R$72,0)),"")
A10: =IFERROR(INDEX(Comparison!$A$5:$A$72,MATCH(6,Comparison!$R$5:$R$72,0)),"") | D10: =IFERROR(INDEX(Comparison!$B$5:$B$72,MATCH(6,Comparison!$R$5:$R$72,0)),"")
A11: =IFERROR(INDEX(Comparison!$A$5:$A$72,MATCH(7,Comparison!$R$5:$R$72,0)),"") | D11: =IFERROR(INDEX(Comparison!$B$5:$B$72,MATCH(7,Comparison!$R$5:$R$72,0)),"")
A12: =IFERROR(INDEX(Comparison!$A$5:$A$72,MATCH(8,Comparison!$R$5:$R$72,0)),"") | D12: =IFERROR(INDEX(Comparison!$B$5:$B$72,MATCH(8,Comparison!$R$5:$R$72,0)),"")
A13: =IFERROR(INDEX(Comparison!$A$5:$A$72,MATCH(9,Comparison!$R$5:$R$72,0)),"") | D13: =IFERROR(INDEX(Comparison!$B$5:$B$72,MATCH(9,Comparison!$R$5:$R$72,0)),"")
A14: =IFERROR(INDEX(Comparison!$A$5:$A$72,MATCH(10,Comparison!$R$5:$R$72,0)),"") | D14: =IFERROR(INDEX(Comparison!$B$5:$B$72,MATCH(10,Comparison!$R$5:$R$72,0)),"")
A16: PageBinder and just one other program | D16: =COUNTIF(Comparison!$O$5:$O$72,"PageBinder and one other") -> 5
A17: =IFERROR(INDEX(Comparison!$A$5:$A$72,MATCH(1,Comparison!$S$5:$S$72,0)),"") -> Table cell colours and per-side borders | D17: =IFERROR(INDEX(Comparison!$B$5:$B$72,MATCH(1,Comparison!$S$5:$S$72,0)),"") -> Yes: fill, row height, column width, borders per cell
A18: =IFERROR(INDEX(Comparison!$A$5:$A$72,MATCH(2,Comparison!$S$5:$S$72,0)),"") -> Insert an attached PDF's pages as a printout on the page | D18: =IFERROR(INDEX(Comparison!$B$5:$B$72,MATCH(2,Comparison!$S$5:$S$72,0)),"") -> Yes
A19: =IFERROR(INDEX(Comparison!$A$5:$A$72,MATCH(3,Comparison!$S$5:$S$72,0)),"") -> Pages laid out on real sheets, with the page border and margins visible while editing | D19: =IFERROR(INDEX(Comparison!$B$5:$B$72,MATCH(3,Comparison!$S$5:$S$72,0)),"") -> Yes
A20: =IFERROR(INDEX(Comparison!$A$5:$A$72,MATCH(4,Comparison!$S$5:$S$72,0)),"") -> Paper size and orientation per page or notebook (Letter, A4, Tabloid, ...) | D20: =IFERROR(INDEX(Comparison!$B$5:$B$72,MATCH(4,Comparison!$S$5:$S$72,0)),"") -> Yes
A21: =IFERROR(INDEX(Comparison!$A$5:$A$72,MATCH(5,Comparison!$S$5:$S$72,0)),"") -> Print a whole section or notebook as one document | D21: =IFERROR(INDEX(Comparison!$B$5:$B$72,MATCH(5,Comparison!$S$5:$S$72,0)),"") -> Yes
A22: =IFERROR(INDEX(Comparison!$A$5:$A$72,MATCH(6,Comparison!$S$5:$S$72,0)),"") | D22: =IFERROR(INDEX(Comparison!$B$5:$B$72,MATCH(6,Comparison!$S$5:$S$72,0)),"")
A23: =IFERROR(INDEX(Comparison!$A$5:$A$72,MATCH(7,Comparison!$S$5:$S$72,0)),"") | D23: =IFERROR(INDEX(Comparison!$B$5:$B$72,MATCH(7,Comparison!$S$5:$S$72,0)),"")
A24: =IFERROR(INDEX(Comparison!$A$5:$A$72,MATCH(8,Comparison!$S$5:$S$72,0)),"") | D24: =IFERROR(INDEX(Comparison!$B$5:$B$72,MATCH(8,Comparison!$S$5:$S$72,0)),"")
A25: =IFERROR(INDEX(Comparison!$A$5:$A$72,MATCH(9,Comparison!$S$5:$S$72,0)),"") | D25: =IFERROR(INDEX(Comparison!$B$5:$B$72,MATCH(9,Comparison!$S$5:$S$72,0)),"")
A26: =IFERROR(INDEX(Comparison!$A$5:$A$72,MATCH(10,Comparison!$S$5:$S$72,0)),"") | D26: =IFERROR(INDEX(Comparison!$B$5:$B$72,MATCH(10,Comparison!$S$5:$S$72,0)),"")
A28: PageBinder and a few others (a third or fewer) | D28: =COUNTIF(Comparison!$O$5:$O$72,"PageBinder and a few others") -> 4
A29: =IFERROR(INDEX(Comparison!$A$5:$A$72,MATCH(1,Comparison!$T$5:$T$72,0)),"") -> Folder tree on disk mirrors the app's hierarchy | D29: =IFERROR(INDEX(Comparison!$B$5:$B$72,MATCH(1,Comparison!$T$5:$T$72,0)),"") -> Yes
A30: =IFERROR(INDEX(Comparison!$A$5:$A$72,MATCH(2,Comparison!$T$5:$T$72,0)),"") -> Notes readable without the app | D30: =IFERROR(INDEX(Comparison!$B$5:$B$72,MATCH(2,Comparison!$T$5:$T$72,0)),"") -> Yes: every page keeps a page.html copy that opens in any browser
A31: =IFERROR(INDEX(Comparison!$A$5:$A$72,MATCH(3,Comparison!$T$5:$T$72,0)),"") -> Freeform canvas: place items anywhere on the page | D31: =IFERROR(INDEX(Comparison!$B$5:$B$72,MATCH(3,Comparison!$T$5:$T$72,0)),"") -> Yes: every page is a canvas
A32: =IFERROR(INDEX(Comparison!$A$5:$A$72,MATCH(4,Comparison!$T$5:$T$72,0)),"") -> Published results at very large size | D32: =IFERROR(INDEX(Comparison!$B$5:$B$72,MATCH(4,Comparison!$T$5:$T$72,0)),"") -> Yes: 50,000 pages measured; type-ahead in milliseconds
A33: =IFERROR(INDEX(Comparison!$A$5:$A$72,MATCH(5,Comparison!$T$5:$T$72,0)),"") | D33: =IFERROR(INDEX(Comparison!$B$5:$B$72,MATCH(5,Comparison!$T$5:$T$72,0)),"")
A34: =IFERROR(INDEX(Comparison!$A$5:$A$72,MATCH(6,Comparison!$T$5:$T$72,0)),"") | D34: =IFERROR(INDEX(Comparison!$B$5:$B$72,MATCH(6,Comparison!$T$5:$T$72,0)),"")
A35: =IFERROR(INDEX(Comparison!$A$5:$A$72,MATCH(7,Comparison!$T$5:$T$72,0)),"") | D35: =IFERROR(INDEX(Comparison!$B$5:$B$72,MATCH(7,Comparison!$T$5:$T$72,0)),"")
A36: =IFERROR(INDEX(Comparison!$A$5:$A$72,MATCH(8,Comparison!$T$5:$T$72,0)),"") | D36: =IFERROR(INDEX(Comparison!$B$5:$B$72,MATCH(8,Comparison!$T$5:$T$72,0)),"")
A37: =IFERROR(INDEX(Comparison!$A$5:$A$72,MATCH(9,Comparison!$T$5:$T$72,0)),"") | D37: =IFERROR(INDEX(Comparison!$B$5:$B$72,MATCH(9,Comparison!$T$5:$T$72,0)),"")
A38: =IFERROR(INDEX(Comparison!$A$5:$A$72,MATCH(10,Comparison!$T$5:$T$72,0)),"") | D38: =IFERROR(INDEX(Comparison!$B$5:$B$72,MATCH(10,Comparison!$T$5:$T$72,0)),"")
A40: Most other programs have these; PageBinder does not | D40: =COUNTIF(Comparison!$O$5:$O$72,"Most others, not PageBinder") -> 5
A41: =IFERROR(INDEX(Comparison!$A$5:$A$72,MATCH(1,Comparison!$U$5:$U$72,0)),"") -> Tags | D41: =IFERROR(INDEX(Comparison!$B$5:$B$72,MATCH(1,Comparison!$U$5:$U$72,0)),"") -> No
A42: =IFERROR(INDEX(Comparison!$A$5:$A$72,MATCH(2,Comparison!$U$5:$U$72,0)),"") -> Math formulas | D42: =IFERROR(INDEX(Comparison!$B$5:$B$72,MATCH(2,Comparison!$U$5:$U$72,0)),"") -> No
A43: =IFERROR(INDEX(Comparison!$A$5:$A$72,MATCH(3,Comparison!$U$5:$U$72,0)),"") -> Code blocks with highlighting | D43: =IFERROR(INDEX(Comparison!$B$5:$B$72,MATCH(3,Comparison!$U$5:$U$72,0)),"") -> No
...

Sheet Comparison
A1: Note-taking programs compared, feature by feature
A2: Checked 25 September 2026 against each project's README, documentation, or website (see the Sources sheet). Cells start with Yes, No, Partial, Plugin, Paid, N/A, or Not stated so the two grey columns can count them. A trailing * marks an entry from general knowledge of the project rather than a page read on that date: verify it before relying on it.
A4: Feature | B4: PageBinder | C4: Joplin | D4: Obsidian | E4: Logseq | F4: Trilium Notes | G4: SiYuan | H4: AFFiNE | I4: AppFlowy | J4: Anytype | K4: Notesnook | L4: Zim Desktop Wiki | M4: Xournal++ | N4: Programs answering Yes (of 12) | O4: Pattern | P4: What the row means | Q4: Category | R4: # Only PageBinder | S4: # PageBinder and one other | T4: # PageBinder and a few others | U4: # Most others, not PageBinder | V4: # All except PageBinder | W4: # Shared by all
A5: Basics | Q5: Basics
A6: Typical fit (neutral description) | B6: Printable documents with large attachments, kept as plain folders on your own disk | C6: Markdown notes synced across many devices | D6: Linked Markdown knowledge base with a large plugin ecosystem | E6: Outliner and daily journal with backlinks and whiteboards | F6: Deep hierarchical knowledge base, self-hosted sync | G6: Block-based knowledge base kept on your own device | H6: Documents plus whiteboard, built for collaboration | I6: Notion-style workspace with databases, self-hostable | J6: Encrypted object-based workspace with peer-to-peer sync | K6: Encrypted notes synced through the vendor's service | L6: Plain-text desktop wiki | M6: Handwritten notes and PDF annotation on paper-like pages | N6: =COUNTIF(B6:M6,"Yes*") -> 0 | O6: =IF(COUNTIF(B6:M6,"Yes*")=12,"Shared by all",IF(AND(LEFT(B6,3)="Yes",COUNTIF(B6:M6,"Yes*")=1),"Only PageBinder",IF(AND(LEFT(B6,3)="Yes",COUNTIF(B6:M6,"Yes*")=2),"PageBinder and one other",IF(AND(LEFT(B6,3)<>"Yes",COUNTIF(B6:M6,"Yes*")=11),"All except PageBinder",IF(AND(LEFT(B6,3)<>"Yes",COUNTIF(B6:M6,"Yes*")>=9),"Most others, not PageBinder",IF(AND(LEFT(B6,3)="Yes",COUNTIF(B6:M6,"Yes*")<=4),"PageBinder and a few others","")))))) | P6: One-line description of what each program is designed around. | Q6: Basics | R6: =IF(O6="Only PageBinder",COUNTIF(O$5:O6,"Only PageBinder"),"") | S6: =IF(O6="PageBinder and one other",COUNTIF(O$5:O6,"PageBinder and one other"),"") | T6: =IF(O6="PageBinder and a few others",COUNTIF(O$5:O6,"PageBinder and a few others"),"") | U6: =IF(O6="Most others, not PageBinder",COUNTIF(O$5:O6,"Most others, not PageBinder"),"") | V6: =IF(O6="All except PageBinder",COUNTIF(O$5:O6,"All except PageBinder"),"") | W6: =IF(O6="Shared by all",COUNTIF(O$5:O6,"Shared by all"),"")
A7: Licence | B7: MIT (open source) | C7: AGPL-3.0 | D7: Proprietary (closed source; free for personal and commercial use) | E7: AGPL-3.0 | F7: AGPL-3.0 | G7: AGPL-3.0 | H7: MIT (community edition) | I7: AGPL-3.0 | J7: Any Source Available License 1.0 (source available, not OSI open source) | K7: GPL-3.0 | L7: GPL-2.0 or later | M7: GPL-2.0 | N7: =COUNTIF(B7:M7,"Yes*") -> 0 | O7: =IF(COUNTIF(B7:M7,"Yes*")=12,"Shared by all",IF(AND(LEFT(B7,3)="Yes",COUNTIF(B7:M7,"Yes*")=1),"Only PageBinder",IF(AND(LEFT(B7,3)="Yes",COUNTIF(B7:M7,"Yes*")=2),"PageBinder and one other",IF(AND(LEFT(B7,3)<>"Yes",COUNTIF(B7:M7,"Yes*")=11),"All except PageBinder",IF(AND(LEFT(B7,3)<>"Yes",COUNTIF(B7:M7,"Yes*")>=9),"Most others, not PageBinder",IF(AND(LEFT(B7,3)="Yes",COUNTIF(B7:M7,"Yes*")<=4),"PageBinder and a few others","")))))) | P7: Obsidian's code is not open; GitHub hosts its releases and plugins only. | Q7: Basics | R7: =IF(O7="Only PageBinder",COUNTIF(O$5:O7,"Only PageBinder"),"") | S7: =IF(O7="PageBinder and one other",COUNTIF(O$5:O7,"PageBinder and one other"),"") | T7: =IF(O7="PageBinder and a few others",COUNTIF(O$5:O7,"PageBinder and a few others"),"") | U7: =IF(O7="Most others, not PageBinder",COUNTIF(O$5:O7,"Most others, not PageBinder"),"") | V7: =IF(O7="All except PageBinder",COUNTIF(O$5:O7,"All except PageBinder"),"") | W7: =IF(O7="Shared by all",COUNTIF(O$5:O7,"Shared by all"),"")
A8: Price | B8: Free | C8: Free; Joplin Cloud sync is paid | D8: Free; Sync and Publish add-ons are paid | E8: Free; Logseq Sync is paid | F8: Free | G8: Free locally; PRO tier for cloud and third-party sync | H8: Free locally; cloud plans are paid | I8: Free; Pro plans for cloud features | J8: Free (Explorer); paid tiers | K8: Free; paid plans add attachment storage | L8: Free | M8: Free | N8: =COUNTIF(B8:M8,"Yes*") -> 0 | O8: =IF(COUNTIF(B8:M8,"Yes*")=12,"Shared by all",IF(AND(LEFT(B8,3)="Yes",COUNTIF(B8:M8,"Yes*")=1),"Only PageBinder",IF(AND(LEFT(B8,3)="Yes",COUNTIF(B8:M8,"Yes*")=2),"PageBinder and one other",IF(AND(LEFT(B8,3)<>"Yes",COUNTIF(B8:M8,"Yes*")=11),"All except PageBinder",IF(AND(LEFT(B8,3)<>"Yes",COUNTIF(B8:M8,"Yes*")>=9),"Most others, not PageBinder",IF(AND(LEFT(B8,3)="Yes",COUNTIF(B8:M8,"Yes*")<=4),"PageBinder and a few others","")))))) | Q8: Basics | R8: =IF(O8="Only PageBinder",COUNTIF(O$5:O8,"Only PageBinder"),"") | S8: =IF(O8="PageBinder and one other",COUNTIF(O$5:O8,"PageBinder and one other"),"") | T8: =IF(O8="PageBinder and a few others",COUNTIF(O$5:O8,"PageBinder and a few others"),"") | U8: =IF(O8="Most others, not PageBinder",COUNTIF(O$5:O8,"Most others, not PageBinder"),"") | V8: =IF(O8="All except PageBinder",COUNTIF(O$5:O8,"All except PageBinder"),"") | W8: =IF(O8="Shared by all",COUNTIF(O$5:O8,"Shared by all"),"")
A9: Desktop platforms | B9: macOS, Windows (Linux builds from source, untested) | C9: Windows, macOS, Linux | D9: Windows, macOS, Linux | E9: Windows, macOS, Linux | F9: Windows, macOS, Linux, plus self-hosted web app | G9: Windows, macOS, Linux, plus Docker server | H9: Windows, macOS, Linux, plus web | I9: Windows, macOS, Linux, plus web | J9: Windows, macOS, Linux | K9: Windows, macOS, Linux, plus web | L9: Linux, Windows, macOS | M9: Linux, macOS, Windows, ChromeOS | N9: =COUNTIF(B9:M9,"Yes*") -> 0 | O9: =IF(COUNTIF(B9:M9,"Yes*")=12,"Shared by all",IF(AND(LEFT(B9,3)="Yes",COUNTIF(B9:M9,"Yes*")=1),"Only PageBinder",IF(AND(LEFT(B9,3)="Yes",COUNTIF(B9:M9,"Yes*")=2),"PageBinder and one other",IF(AND(LEFT(B9,3)<>"Yes",COUNTIF(B9:M9,"Yes*")=11),"All except PageBinder",IF(AND(LEFT(B9,3)<>"Yes",COUNTIF(B9:M9,"Yes*")>=9),"Most others, not PageBinder",IF(AND(LEFT(B9,3)="Yes",COUNTIF(B9:M9,"Yes*")<=4),"PageBinder and a few others","")))))) | Q9: Basics | R9: =IF(O9="Only PageBinder",COUNTIF(O$5:O9,"Only PageBinder"),"") | S9: =IF(O9="PageBinder and one other",COUNTIF(O$5:O9,"PageBinder and one other"),"") | T9: =IF(O9="PageBinder and a few others",COUNTIF(O$5:O9,"PageBinder and a few others"),"") | U9: =IF(O9="Most others, not PageBinder",COUNTIF(O$5:O9,"Most others, not PageBinder"),"") | V9: =IF(O9="All except PageBinder",COUNTIF(O$5:O9,"All except PageBinder"),"") | W9: =IF(O9="Shared by all",COUNTIF(O$5:O9,"Shared by all"),"")
A10: Mobile apps | B10: No | C10: Yes: iOS, Android | D10: Yes: iOS, Android | E10: Yes: iOS, Android | F10: Partial: web layout; third-party apps | G10: Yes: iOS, Android, HarmonyOS | H10: Yes: iOS, Android (capture and review; whiteboard is desktop) | I10: Yes: iOS, Android | J10: Yes: iOS, Android | K10: Yes: iOS, Android | L10: No | M10: Partial: Android build, limited * | N10: =COUNTIF(B10:M10,"Yes*") -> 8 | O10: =IF(COUNTIF(B10:M10,"Yes*")=12,"Shared by all",IF(AND(LEFT(B10,3)="Yes",COUNTIF(B10:M10,"Yes*")=1),"Only PageBinder",IF(AND(LEFT(B10,3)="Yes",COUNTIF(B10:M10,"Yes*")=2),"PageBinder and one other",IF(AND(LEFT(B10,3)<>"Yes",COUNTIF(B10:M10,"Yes*")=11),"All except PageBinder",IF(AND(LEFT(B10,3)<>"Yes",COUNTIF(B10:M10,"Yes*")>=9),"Most others, not PageBinder",IF(AND(LEFT(B10,3)="Yes",COUNTIF(B10:M10,"Yes*")<=4),"PageBinder and a few others","")))))) | Q10: Basics | R10: =IF(O10="Only PageBinder",COUNTIF(O$5:O10,"Only PageBinder"),"") | S10: =IF(O10="PageBinder and one other",COUNTIF(O$5:O10,"PageBinder and one other"),"") | T10: =IF(O10="PageBinder and a few others",COUNTIF(O$5:O10,"PageBinder and a few others"),"") | U10: =IF(O10="Most others, not PageBinder",COUNTIF(O$5:O10,"Most others, not PageBinder"),"") | V10: =IF(O10="All except PageBinder",COUNTIF(O$5:O10,"All except PageBinder"),"") | W10: =IF(O10="Shared by all",COUNTIF(O$5:O10,"Shared by all"),"")
A11: No account needed | B11: Yes | C11: Yes (account only for Joplin Cloud) | D11: Yes (account only for Sync and Publish) | E11: Yes (account only for Logseq Sync) | F11: Yes | G11: Yes (account only for cloud sync) | H11: Yes for local workspaces | I11: Yes for local use * | J11: Yes: a vault key instead of an email account | K11: No: an email account is required | L11: Yes | M11: Yes | N11: =COUNTIF(B11:M11,"Yes*") -> 11 | O11: =IF(COUNTIF(B11:M11,"Yes*")=12,"Shared by all",IF(AND(LEFT(B11,3)="Yes",COUNTIF(B11:M11,"Yes*")=1),"Only PageBinder",IF(AND(LEFT(B11,3)="Yes",COUNTIF(B11:M11,"Yes*")=2),"PageBinder and one other",IF(AND(LEFT(B11,3)<>"Yes",COUNTIF(B11:M11,"Yes*")=11),"All except PageBinder",IF(AND(LEFT(B11,3)<>"Yes",COUNTIF(B11:M11,"Yes*")>=9),"Most others, not PageBinder",IF(AND(LEFT(B11,3)="Yes",COUNTIF(B11:M11,"Yes*")<=4),"PageBinder and a few others","")))))) | Q11: Basics | R11: =IF(O11="Only PageBinder",COUNTIF(O$5:O11,"Only PageBinder"),"") | S11: =IF(O11="PageBinder and one other",COUNTIF(O$5:O11,"PageBinder and one other"),"") | T11: =IF(O11="PageBinder and a few others",COUNTIF(O$5:O11,"PageBinder and a few others"),"") | U11: =IF(O11="Most others, not PageBinder",COUNTIF(O$5:O11,"Most others, not PageBinder"),"") | V11: =IF(O11="All except PageBinder",COUNTIF(O$5:O11,"All except PageBinder"),"") | W11: =IF(O11="Shared by all",COUNTIF(O$5:O11,"Shared by all"),"")
A12: Works fully offline | B12: Yes | C12: Yes | D12: Yes | E12: Yes | F12: Yes | G12: Yes | H12: Yes (local workspaces) | I12: Yes (offline mode) | J12: Yes | K12: Yes, after signing in * | L12: Yes | M12: Yes | N12: =COUNTIF(B12:M12,"Yes*") -> 12 | O12: =IF(COUNTIF(B12:M12,"Yes*")=12,"Shared by all",IF(AND(LEFT(B12,3)="Yes",COUNTIF(B12:M12,"Yes*")=1),"Only PageBinder",IF(AND(LEFT(B12,3)="Yes",COUNTIF(B12:M12,"Yes*")=2),"PageBinder and one other",IF(AND(LEFT(B12,3)<>"Yes",COUNTIF(B12:M12,"Yes*")=11),"All except PageBinder",IF(AND(LEFT(B12,3)<>"Yes",COUNTIF(B12:M12,"Yes*")>=9),"Most others, not PageBinder",IF(AND(LEFT(B12,3)="Yes",COUNTIF(B12:M12,"Yes*")<=4),"PageBinder and a few others","")))))) -> Shared by all | P12: Shared by every program in the table. | Q12: Basics | R12: =IF(O12="Only PageBinder",COUNTIF(O$5:O12,"Only PageBinder"),"") | S12: =IF(O12="PageBinder and one other",COUNTIF(O$5:O12,"PageBinder and one other"),"") | T12: =IF(O12="PageBinder and a few others",COUNTIF(O$5:O12,"PageBinder and a few others"),"") | U12: =IF(O12="Most others, not PageBinder",COUNTIF(O$5:O12,"Most others, not PageBinder"),"") | V12: =IF(O12="All except PageBinder",COUNTIF(O$5:O12,"All except PageBinder"),"") | W12: =IF(O12="Shared by all",COUNTIF(O$5:O12,"Shared by all"),"") -> 1
A13: Where your notes live | Q13: Where your notes live
A14: How notes are stored | B14: Plain folders and files: notebook, section, and page folders with page.json and page.html | C14: SQLite database plus a resources folder (Markdown inside) | D14: Plain Markdown files in a vault folder | E14: Plain Markdown or Org files in a graph folder | F14: One SQLite database file | G14: Workspace folder of JSON (.sy) files plus an assets folder | H14: Local database per workspace (exportable as .affine) | I14: Local database; cloud or self-hosted server for sync | J14: Local encrypted database | K14: Local encrypted database, synced to the vendor's servers | L14: Plain text files in a folder tree | M14: One .xopp file (compressed XML) per document | N14: =COUNTIF(B14:M14,"Yes*") -> 0 | O14: =IF(COUNTIF(B14:M14,"Yes*")=12,"Shared by all",IF(AND(LEFT(B14,3)="Yes",COUNTIF(B14:M14,"Yes*")=1),"Only PageBinder",IF(AND(LEFT(B14,3)="Yes",COUNTIF(B14:M14,"Yes*")=2),"PageBinder and one other",IF(AND(LEFT(B14,3)<>"Yes",COUNTIF(B14:M14,"Yes*")=11),"All except PageBinder",IF(AND(LEFT(B14,3)<>"Yes",COUNTIF(B14:M14,"Yes*")>=9),"Most others, not PageBinder",IF(AND(LEFT(B14,3)="Yes",COUNTIF(B14:M14,"Yes*")<=4),"PageBinder and a few others","")))))) | Q14: Where your notes live | R14: =IF(O14="Only PageBinder",COUNTIF(O$5:O14,"Only PageBinder"),"") | S14: =IF(O14="PageBinder and one other",COUNTIF(O$5:O14,"PageBinder and one other"),"") | T14: =IF(O14="PageBinder and a few others",COUNTIF(O$5:O14,"PageBinder and a few others"),"") | U14: =IF(O14="Most others, not PageBinder",COUNTIF(O$5:O14,"Most others, not PageBinder"),"") | V14: =IF(O14="All except PageBinder",COUNTIF(O$5:O14,"All except PageBinder"),"") | W14: =IF(O14="Shared by all",COUNTIF(O$5:O14,"Shared by all"),"")
A15: Folder tree on disk mirrors the app's hierarchy | B15: Yes | C15: No | D15: Yes | E15: Partial: flat pages folder; hierarchy by page names | F15: No | G15: Yes: notebook folders with nested document files | H15: No | I15: No | J15: No | K15: No | L15: Yes | M15: N/A: documents are separate files | N15: =COUNTIF(B15:M15,"Yes*") -> 4 | O15: =IF(COUNTIF(B15:M15,"Yes*")=12,"Shared by all",IF(AND(LEFT(B15,3)="Yes",COUNTIF(B15:M15,"Yes*")=1),"Only PageBinder",IF(AND(LEFT(B15,3)="Yes",COUNTIF(B15:M15,"Yes*")=2),"PageBinder and one other",IF(AND(LEFT(B15,3)<>"Yes",COUNTIF(B15:M15,"Yes*")=11),"All except PageBinder",IF(AND(LEFT(B15,3)<>"Yes",COUNTIF(B15:M15,"Yes*")>=9),"Most others, not PageBinder",IF(AND(LEFT(B15,3)="Yes",COUNTIF(B15:M15,"Yes*")<=4),"PageBinder and a few others","")))))) -> PageBinder and a few others | Q15: Where your notes live | R15: =IF(O15="Only PageBinder",COUNTIF(O$5:O15,"Only PageBinder"),"") | S15: =IF(O15="PageBinder and one other",COUNTIF(O$5:O15,"PageBinder and one other"),"") | T15: =IF(O15="PageBinder and a few others",COUNTIF(O$5:O15,"PageBinder and a few others"),"") -> 1 | U15: =IF(O15="Most others, not PageBinder",COUNTIF(O$5:O15,"Most others, not PageBinder"),"") | V15: =IF(O15="All except PageBinder",COUNTIF(O$5:O15,"All except PageBinder"),"") | W15: =IF(O15="Shared by all",COUNTIF(O$5:O15,"Shared by all"),"")
A16: Notes readable without the app | B16: Yes: every page keeps a page.html copy that opens in any browser | C16: Partial: Markdown inside a database; export first | D16: Yes: Markdown | E16: Yes: Markdown or Org | F16: No: database; export first | G16: Partial: JSON files; export for readable copies | H16: No: export first | I16: No: export first | J16: No: encrypted; export first | K16: No: encrypted; export first | L16: Yes: plain text | M16: No: export to PDF first | N16: =COUNTIF(B16:M16,"Yes*") -> 4 | O16: =IF(COUNTIF(B16:M16,"Yes*")=12,"Shared by all",IF(AND(LEFT(B16,3)="Yes",COUNTIF(B16:M16,"Yes*")=1),"Only PageBinder",IF(AND(LEFT(B16,3)="Yes",COUNTIF(B16:M16,"Yes*")=2),"PageBinder and one other",IF(AND(LEFT(B16,3)<>"Yes",COUNTIF(B16:M16,"Yes*")=11),"All except PageBinder",IF(AND(LEFT(B16,3)<>"Yes",COUNTIF(B16:M16,"Yes*")>=9),"Most others, not PageBinder",IF(AND(LEFT(B16,3)="Yes",COUNTIF(B16:M16,"Yes*")<=4),"PageBinder and a few others","")))))) -> PageBinder and a few others | Q16: Where your notes live | R16: =IF(O16="Only PageBinder",COUNTIF(O$5:O16,"Only PageBinder"),"") | S16: =IF(O16="PageBinder and one other",COUNTIF(O$5:O16,"PageBinder and one other"),"") | T16: =IF(O16="PageBinder and a few others",COUNTIF(O$5:O16,"PageBinder and a few others"),"") -> 2 | U16: =IF(O16="Most others, not PageBinder",COUNTIF(O$5:O16,"Most others, not PageBinder"),"") | V16: =IF(O16="All except PageBinder",COUNTIF(O$5:O16,"All except PageBinder"),"") | W16: =IF(O16="Shared by all",COUNTIF(O$5:O16,"Shared by all"),"")
A17: Attachments kept beside the note as ordinary files | B17: Yes: in the page's own attachments folder, original name shown | C17: Partial: resources folder, files renamed by ID | D17: Yes | E17: Yes: assets folder | F17: No: stored inside the database | G17: Yes: assets folder, files renamed * | H17: No | I17: No | J17: No | K17: No | L17: Yes: attachment folder per page | M17: No | N17: =COUNTIF(B17:M17,"Yes*") -> 5 | O17: =IF(COUNTIF(B17:M17,"Yes*")=12,"Shared by all",IF(AND(LEFT(B17,3)="Yes",COUNTIF(B17:M17,"Yes*")=1),"Only PageBinder",IF(AND(LEFT(B17,3)="Yes",COUNTIF(B17:M17,"Yes*")=2),"PageBinder and one other",IF(AND(LEFT(B17,3)<>"Yes",COUNTIF(B17:M17,"Yes*")=11),"All except PageBinder",IF(AND(LEFT(B17,3)<>"Yes",COUNTIF(B17:M17,"Yes*")>=9),"Most others, not PageBinder",IF(AND(LEFT(B17,3)="Yes",COUNTIF(B17:M17,"Yes*")<=4),"PageBinder and a few others","")))))) | Q17: Where your notes live | R17: =IF(O17="Only PageBinder",COUNTIF(O$5:O17,"Only PageBinder"),"") | S17: =IF(O17="PageBinder and one other",COUNTIF(O$5:O17,"PageBinder and one other"),"") | T17: =IF(O17="PageBinder and a few others",COUNTIF(O$5:O17,"PageBinder and a few others"),"") | U17: =IF(O17="Most others, not PageBinder",COUNTIF(O$5:O17,"Most others, not PageBinder"),"") | V17: =IF(O17="All except PageBinder",COUNTIF(O$5:O17,"All except PageBinder"),"") | W17: =IF(O17="Shared by all",COUNTIF(O$5:O17,"Shared by all"),"")
A18: Large attachments (videos, scans) with no size limit | B18: Yes: no limit beyond disk space; designed for 500 GB notebooks | C18: Yes locally; sync targets impose their own limits | D18: Yes | E18: Yes | F18: Partial: stored in the database; large files discouraged * | G18: Yes | H18: Partial: cloud plans have storage limits | I18: Partial: cloud plans have storage limits * | J18: Partial: storage tiers * | K18: No: 10 MB per file on the free plan; larger on paid plans | L18: Yes | M18: No: not designed for attachments | N18: =COUNTIF(B18:M18,"Yes*") -> 6 | O18: =IF(COUNTIF(B18:M18,"Yes*")=12,"Shared by all",IF(AND(LEFT(B18,3)="Yes",COUNTIF(B18:M18,"Yes*")=1),"Only PageBinder",IF(AND(LEFT(B18,3)="Yes",COUNTIF(B18:M18,"Yes*")=2),"PageBinder and one other",IF(AND(LEFT(B18,3)<>"Yes",COUNTIF(B18:M18,"Yes*")=11),"All except PageBinder",IF(AND(LEFT(B18,3)<>"Yes",COUNTIF(B18:M18,"Yes*")>=9),"Most others, not PageBinder",IF(AND(LEFT(B18,3)="Yes",COUNTIF(B18:M18,"Yes*")<=4),"PageBinder and a few others","")))))) | Q18: Where your notes live | R18: =IF(O18="Only PageBinder",COUNTIF(O$5:O18,"Only PageBinder"),"") | S18: =IF(O18="PageBinder and one other",COUNTIF(O$5:O18,"PageBinder and one other"),"") | T18: =IF(O18="PageBinder and a few others",COUNTIF(O$5:O18,"PageBinder and a few others"),"") | U18: =IF(O18="Most others, not PageBinder",COUNTIF(O$5:O18,"Most others, not PageBinder"),"") | V18: =IF(O18="All except PageBinder",COUNTIF(O$5:O18,"All except PageBinder"),"") | W18: =IF(O18="Shared by all",COUNTIF(O$5:O18,"Shared by all"),"")
A19: Back up by copying a folder with any tool | B19: Yes: copy the notebook folder (leave out the .index cache) | C19: Partial: copy the profile folder while closed, or export JEX | D19: Yes | E19: Yes | F19: Partial: one database file; built-in backups | G19: Yes: copy the workspace folder | H19: No: export the workspace instead | I19: No | J19: No: export instead | K19: No: export instead | L19: Yes | M19: Yes | N19: =COUNTIF(B19:M19,"Yes*") -> 6 | O19: =IF(COUNTIF(B19:M19,"Yes*")=12,"Shared by all",IF(AND(LEFT(B19,3)="Yes",COUNTIF(B19:M19,"Yes*")=1),"Only PageBinder",IF(AND(LEFT(B19,3)="Yes",COUNTIF(B19:M19,"Yes*")=2),"PageBinder and one other",IF(AND(LEFT(B19,3)<>"Yes",COUNTIF(B19:M19,"Yes*")=11),"All except PageBinder",IF(AND(LEFT(B19,3)<>"Yes",COUNTIF(B19:M19,"Yes*")>=9),"Most others, not PageBinder",IF(AND(LEFT(B19,3)="Yes",COUNTIF(B19:M19,"Yes*")<=4),"PageBinder and a few others","")))))) | Q19: Where your notes live | R19: =IF(O19="Only PageBinder",COUNTIF(O$5:O19,"Only PageBinder"),"") | S19: =IF(O19="PageBinder and one other",COUNTIF(O$5:O19,"PageBinder and one other"),"") | T19: =IF(O19="PageBinder and a few others",COUNTIF(O$5:O19,"PageBinder and a few others"),"") | U19: =IF(O19="Most others, not PageBinder",COUNTIF(O$5:O19,"Most others, not PageBinder"),"") | V19: =IF(O19="All except PageBinder",COUNTIF(O$5:O19,"All except PageBinder"),"") | W19: =IF(O19="Shared by all",COUNTIF(O$5:O19,"Shared by all"),"")
A20: Notebook made on a Mac opens on Windows unchanged | B20: Yes: verified automatically on every release | C20: Yes | D20: Yes | E20: Yes | F20: Yes | G20: Yes | H20: Yes * | I20: Yes * | J20: Yes * | K20: Yes via sync | L20: Yes | M20: Yes | N20: =COUNTIF(B20:M20,"Yes*") -> 12 | O20: =IF(COUNTIF(B20:M20,"Yes*")=12,"Shared by all",IF(AND(LEFT(B20,3)="Yes",COUNTIF(B20:M20,"Yes*")=1),"Only PageBinder",IF(AND(LEFT(B20,3)="Yes",COUNTIF(B20:M20,"Yes*")=2),"PageBinder and one other",IF(AND(LEFT(B20,3)<>"Yes",COUNTIF(B20:M20,"Yes*")=11),"All except PageBinder",IF(AND(LEFT(B20,3)<>"Yes",COUNTIF(B20:M20,"Yes*")>=9),"Most others, not PageBinder",IF(AND(LEFT(B20,3)="Yes",COUNTIF(B20:M20,"Yes*")<=4),"PageBinder and a few others","")))))) -> Shared by all | Q20: Where your notes live | R20: =IF(O20="Only PageBinder",COUNTIF(O$5:O20,"Only PageBinder"),"") | S20: =IF(O20="PageBinder and one other",COUNTIF(O$5:O20,"PageBinder and one other"),"") | T20: =IF(O20="PageBinder and a few others",COUNTIF(O$5:O20,"PageBinder and a few others"),"") | U20: =IF(O20="Most others, not PageBinder",COUNTIF(O$5:O20,"Most others, not PageBinder"),"") | V20: =IF(O20="All except PageBinder",COUNTIF(O$5:O20,"All except PageBinder"),"") | W20: =IF(O20="Shared by all",COUNTIF(O$5:O20,"Shared by all"),"") -> 2
A21: Organising | Q21: Organising
A22: Hierarchy | B22: Notebook > section group > section > page (OneNote style) | C22: Nested notebooks > notes | D22: Folders > Markdown files | E22: Flat pages with namespaces; daily journal | F22: Tree of unlimited depth; a note can appear in several places | G22: Notebooks > nested documents | H22: Docs and collections | I22: Nested pages | J22: Objects with types, sets, and collections | K22: Notebooks > sub-notebooks > notes | L22: Page tree | M22: Separate documents, each of many pages | N22: =COUNTIF(B22:M22,"Yes*") -> 0 | O22: =IF(COUNTIF(B22:M22,"Yes*")=12,"Shared by all",IF(AND(LEFT(B22,3)="Yes",COUNTIF(B22:M22,"Yes*")=1),"Only PageBinder",IF(AND(LEFT(B22,3)="Yes",COUNTIF(B22:M22,"Yes*")=2),"PageBinder and one other",IF(AND(LEFT(B22,3)<>"Yes",COUNTIF(B22:M22,"Yes*")=11),"All except PageBinder",IF(AND(LEFT(B22,3)<>"Yes",COUNTIF(B22:M22,"Yes*")>=9),"Most others, not PageBinder",IF(AND(LEFT(B22,3)="Yes",COUNTIF(B22:M22,"Yes*")<=4),"PageBinder and a few others","")))))) | Q22: Organising | R22: =IF(O22="Only PageBinder",COUNTIF(O$5:O22,"Only PageBinder"),"") | S22: =IF(O22="PageBinder and one other",COUNTIF(O$5:O22,"PageBinder and one other"),"") | T22: =IF(O22="PageBinder and a few others",COUNTIF(O$5:O22,"PageBinder and a few others"),"") | U22: =IF(O22="Most others, not PageBinder",COUNTIF(O$5:O22,"Most others, not PageBinder"),"") | V22: =IF(O22="All except PageBinder",COUNTIF(O$5:O22,"All except PageBinder"),"") | W22: =IF(O22="Shared by all",COUNTIF(O$5:O22,"Shared by all"),"")
A23: Tags | B23: No | C23: Yes | D23: Yes | E23: Yes | F23: Yes (labels and attributes) | G23: Yes | H23: Yes | I23: Partial * | J23: Yes (relations) | K23: Yes | L23: Yes | M23: No | N23: =COUNTIF(B23:M23,"Yes*") -> 9 | O23: =IF(COUNTIF(B23:M23,"Yes*")=12,"Shared by all",IF(AND(LEFT(B23,3)="Yes",COUNTIF(B23:M23,"Yes*")=1),"Only PageBinder",IF(AND(LEFT(B23,3)="Yes",COUNTIF(B23:M23,"Yes*")=2),"PageBinder and one other",IF(AND(LEFT(B23,3)<>"Yes",COUNTIF(B23:M23,"Yes*")=11),"All except PageBinder",IF(AND(LEFT(B23,3)<>"Yes",COUNTIF(B23:M23,"Yes*")>=9),"Most others, not PageBinder",IF(AND(LEFT(B23,3)="Yes",COUNTIF(B23:M23,"Yes*")<=4),"PageBinder and a few others","")))))) -> Most others, not PageBinder | Q23: Organising | R23: =IF(O23="Only PageBinder",COUNTIF(O$5:O23,"Only PageBinder"),"") | S23: =IF(O23="PageBinder and one other",COUNTIF(O$5:O23,"PageBinder and one other"),"") | T23: =IF(O23="PageBinder and a few others",COUNTIF(O$5:O23,"PageBinder and a few others"),"") | U23: =IF(O23="Most others, not PageBinder",COUNTIF(O$5:O23,"Most others, not PageBinder"),"") -> 1 | V23: =IF(O23="All except PageBinder",COUNTIF(O$5:O23,"All except PageBinder"),"") | W23: =IF(O23="Shared by all",COUNTIF(O$5:O23,"Shared by all"),"")
A24: Links between pages with backlinks | B24: No | C24: Partial: links; backlinks via plugin | D24: Yes | E24: Yes | F24: Yes | G24: Yes | H24: Yes | I24: Partial: mentions * | J24: Yes | K24: Partial: internal links * | L24: Yes | M24: No | N24: =COUNTIF(B24:M24,"Yes*") -> 7 | O24: =IF(COUNTIF(B24:M24,"Yes*")=12,"Shared by all",IF(AND(LEFT(B24,3)="Yes",COUNTIF(B24:M24,"Yes*")=1),"Only PageBinder",IF(AND(LEFT(B24,3)="Yes",COUNTIF(B24:M24,"Yes*")=2),"PageBinder and one other",IF(AND(LEFT(B24,3)<>"Yes",COUNTIF(B24:M24,"Yes*")=11),"All except PageBinder",IF(AND(LEFT(B24,3)<>"Yes",COUNTIF(B24:M24,"Yes*")>=9),"Most others, not PageBinder",IF(AND(LEFT(B24,3)="Yes",COUNTIF(B24:M24,"Yes*")<=4),"PageBinder and a few others","")))))) | Q24: Organising | R24: =IF(O24="Only PageBinder",COUNTIF(O$5:O24,"Only PageBinder"),"") | S24: =IF(O24="PageBinder and one other",COUNTIF(O$5:O24,"PageBinder and one other"),"") | T24: =IF(O24="PageBinder and a few others",COUNTIF(O$5:O24,"PageBinder and a few others"),"") | U24: =IF(O24="Most others, not PageBinder",COUNTIF(O$5:O24,"Most others, not PageBinder"),"") | V24: =IF(O24="All except PageBinder",COUNTIF(O$5:O24,"All except PageBinder"),"") | W24: =IF(O24="Shared by all",COUNTIF(O$5:O24,"Shared by all"),"")
A25: Graph view of links | B25: No | C25: Plugin | D25: Yes | E25: Yes | F25: Yes (note map) | G25: Yes | H25: No | I25: No | J25: Yes | K25: No | L25: No | M25: No | N25: =COUNTIF(B25:M25,"Yes*") -> 5 | O25: =IF(COUNTIF(B25:M25,"Yes*")=12,"Shared by all",IF(AND(LEFT(B25,3)="Yes",COUNTIF(B25:M25,"Yes*")=1),"Only PageBinder",IF(AND(LEFT(B25,3)="Yes",COUNTIF(B25:M25,"Yes*")=2),"PageBinder and one other",IF(AND(LEFT(B25,3)<>"Yes",COUNTIF(B25:M25,"Yes*")=11),"All except PageBinder",IF(AND(LEFT(B25,3)<>"Yes",COUNTIF(B25:M25,"Yes*")>=9),"Most others, not PageBinder",IF(AND(LEFT(B25,3)="Yes",COUNTIF(B25:M25,"Yes*")<=4),"PageBinder and a few others","")))))) | Q25: Organising | R25: =IF(O25="Only PageBinder",COUNTIF(O$5:O25,"Only PageBinder"),"") | S25: =IF(O25="PageBinder and one other",COUNTIF(O$5:O25,"PageBinder and one other"),"") | T25: =IF(O25="PageBinder and a few others",COUNTIF(O$5:O25,"PageBinder and a few others"),"") | U25: =IF(O25="Most others, not PageBinder",COUNTIF(O$5:O25,"Most others, not PageBinder"),"") | V25: =IF(O25="All except PageBinder",COUNTIF(O$5:O25,"All except PageBinder"),"") | W25: =IF(O25="Shared by all",COUNTIF(O$5:O25,"Shared by all"),"")
A26: Outliner (every paragraph is a block) | B26: No | C26: No | D26: Plugin | E26: Yes | F26: No | G26: Yes | H26: Partial: block editor | I26: Partial: block editor | J26: Yes | K26: No | L26: No | M26: No | N26: =COUNTIF(B26:M26,"Yes*") -> 3 | O26: =IF(COUNTIF(B26:M26,"Yes*")=12,"Shared by all",IF(AND(LEFT(B26,3)="Yes",COUNTIF(B26:M26,"Yes*")=1),"Only PageBinder",IF(AND(LEFT(B26,3)="Yes",COUNTIF(B26:M26,"Yes*")=2),"PageBinder and one other",IF(AND(LEFT(B26,3)<>"Yes",COUNTIF(B26:M26,"Yes*")=11),"All except PageBinder",IF(AND(LEFT(B26,3)<>"Yes",COUNTIF(B26:M26,"Yes*")>=9),"Most others, not PageBinder",IF(AND(LEFT(B26,3)="Yes",COUNTIF(B26:M26,"Yes*")<=4),"PageBinder and a few others","")))))) | Q26: Organising | R26: =IF(O26="Only PageBinder",COUNTIF(O$5:O26,"Only PageBinder"),"") | S26: =IF(O26="PageBinder and one other",COUNTIF(O$5:O26,"PageBinder and one other"),"") | T26: =IF(O26="PageBinder and a few others",COUNTIF(O$5:O26,"PageBinder and a few others"),"") | U26: =IF(O26="Most others, not PageBinder",COUNTIF(O$5:O26,"Most others, not PageBinder"),"") | V26: =IF(O26="All except PageBinder",COUNTIF(O$5:O26,"All except PageBinder"),"") | W26: =IF(O26="Shared by all",COUNTIF(O$5:O26,"Shared by all"),"")
A27: Editing the page | Q27: Editing the page
A28: Freeform canvas: place items anywhere on the page | B28: Yes: every page is a canvas | C28: No | D28: Partial: separate Canvas files | E28: Partial: separate Whiteboards | F28: Partial: separate Canvas note type | G28: No | H28: Yes: edgeless mode on any doc | I28: No | J28: No | K28: No | L28: No | M28: Yes: paper-like pages | N28: =COUNTIF(B28:M28,"Yes*") -> 3 | O28: =IF(COUNTIF(B28:M28,"Yes*")=12,"Shared by all",IF(AND(LEFT(B28,3)="Yes",COUNTIF(B28:M28,"Yes*")=1),"Only PageBinder",IF(AND(LEFT(B28,3)="Yes",COUNTIF(B28:M28,"Yes*")=2),"PageBinder and one other",IF(AND(LEFT(B28,3)<>"Yes",COUNTIF(B28:M28,"Yes*")=11),"All except PageBinder",IF(AND(LEFT(B28,3)<>"Yes",COUNTIF(B28:M28,"Yes*")>=9),"Most others, not PageBinder",IF(AND(LEFT(B28,3)="Yes",COUNTIF(B28:M28,"Yes*")<=4),"PageBinder and a few others","")))))) -> PageBinder and a few others | Q28: Editing the page | R28: =IF(O28="Only PageBinder",COUNTIF(O$5:O28,"Only PageBinder"),"") | S28: =IF(O28="PageBinder and one other",COUNTIF(O$5:O28,"PageBinder and one other"),"") | T28: =IF(O28="PageBinder and a few others",COUNTIF(O$5:O28,"PageBinder and a few others"),"") -> 3 | U28: =IF(O28="Most others, not PageBinder",COUNTIF(O$5:O28,"Most others, not PageBinder"),"") | V28: =IF(O28="All except PageBinder",COUNTIF(O$5:O28,"All except PageBinder"),"") | W28: =IF(O28="Shared by all",COUNTIF(O$5:O28,"Shared by all"),"")
A29: Editing style | B29: Rich text (what you see is what you print) | C29: Markdown, plus a rich text editor | D29: Markdown with live preview | E29: Markdown or Org outliner | F29: Rich text (CKEditor) and code notes | G29: Block editor (Markdown-like, WYSIWYG) | H29: Block editor | I29: Block editor | J29: Block editor | K29: Rich text | L29: Wiki text with formatting shown | M29: Handwriting plus text boxes | N29: =COUNTIF(B29:M29,"Yes*") -> 0 | O29: =IF(COUNTIF(B29:M29,"Yes*")=12,"Shared by all",IF(AND(LEFT(B29,3)="Yes",COUNTIF(B29:M29,"Yes*")=1),"Only PageBinder",IF(AND(LEFT(B29,3)="Yes",COUNTIF(B29:M29,"Yes*")=2),"PageBinder and one other",IF(AND(LEFT(B29,3)<>"Yes",COUNTIF(B29:M29,"Yes*")=11),"All except PageBinder",IF(AND(LEFT(B29,3)<>"Yes",COUNTIF(B29:M29,"Yes*")>=9),"Most others, not PageBinder",IF(AND(LEFT(B29,3)="Yes",COUNTIF(B29:M29,"Yes*")<=4),"PageBinder and a few others","")))))) | Q29: Editing the page | R29: =IF(O29="Only PageBinder",COUNTIF(O$5:O29,"Only PageBinder"),"") | S29: =IF(O29="PageBinder and one other",COUNTIF(O$5:O29,"PageBinder and one other"),"") | T29: =IF(O29="PageBinder and a few others",COUNTIF(O$5:O29,"PageBinder and a few others"),"") | U29: =IF(O29="Most others, not PageBinder",COUNTIF(O$5:O29,"Most others, not PageBinder"),"") | V29: =IF(O29="All except PageBinder",COUNTIF(O$5:O29,"All except PageBinder"),"") | W29: =IF(O29="Shared by all",COUNTIF(O$5:O29,"Shared by all"),"")
A30: Tables | B30: Yes | C30: Yes | D30: Yes | E30: Partial: Markdown tables | F30: Yes | G30: Yes | H30: Yes | I30: Yes | J30: Yes | K30: Yes | L30: Plugin (Table Editor) | M30: No | N30: =COUNTIF(B30:M30,"Yes*") -> 9 | O30: =IF(COUNTIF(B30:M30,"Yes*")=12,"Shared by all",IF(AND(LEFT(B30,3)="Yes",COUNTIF(B30:M30,"Yes*")=1),"Only PageBinder",IF(AND(LEFT(B30,3)="Yes",COUNTIF(B30:M30,"Yes*")=2),"PageBinder and one other",IF(AND(LEFT(B30,3)<>"Yes",COUNTIF(B30:M30,"Yes*")=11),"All except PageBinder",IF(AND(LEFT(B30,3)<>"Yes",COUNTIF(B30:M30,"Yes*")>=9),"Most others, not PageBinder",IF(AND(LEFT(B30,3)="Yes",COUNTIF(B30:M30,"Yes*")<=4),"PageBinder and a few others","")))))) | Q30: Editing the page | R30: =IF(O30="Only PageBinder",COUNTIF(O$5:O30,"Only PageBinder"),"") | S30: =IF(O30="PageBinder and one other",COUNTIF(O$5:O30,"PageBinder and one other"),"") | T30: =IF(O30="PageBinder and a few others",COUNTIF(O$5:O30,"PageBinder and a few others"),"") | U30: =IF(O30="Most others, not PageBinder",COUNTIF(O$5:O30,"Most others, not PageBinder"),"") | V30: =IF(O30="All except PageBinder",COUNTIF(O$5:O30,"All except PageBinder"),"") | W30: =IF(O30="Shared by all",COUNTIF(O$5:O30,"Shared by all"),"")
A31: Table cell colours and per-side borders | B31: Yes: fill, row height, column width, borders per cell | C31: Partial: rich text editor only * | D31: No | E31: No | F31: Yes * | G31: No * | H31: No * | I31: No * | J31: Partial: cell background * | K31: Partial: cell background * | L31: No | M31: N/A | N31: =COUNTIF(B31:M31,"Yes*") -> 2 | O31: =IF(COUNTIF(B31:M31,"Yes*")=12,"Shared by all",IF(AND(LEFT(B31,3)="Yes",COUNTIF(B31:M31,"Yes*")=1),"Only PageBinder",IF(AND(LEFT(B31,3)="Yes",COUNTIF(B31:M31,"Yes*")=2),"PageBinder and one other",IF(AND(LEFT(B31,3)<>"Yes",COUNTIF(B31:M31,"Yes*")=11),"All except PageBinder",IF(AND(LEFT(B31,3)<>"Yes",COUNTIF(B31:M31,"Yes*")>=9),"Most others, not PageBinder",IF(AND(LEFT(B31,3)="Yes",COUNTIF(B31:M31,"Yes*")<=4),"PageBinder and a few others","")))))) -> PageBinder and one other | Q31: Editing the page | R31: =IF(O31="Only PageBinder",COUNTIF(O$5:O31,"Only PageBinder"),"") | S31: =IF(O31="PageBinder and one other",COUNTIF(O$5:O31,"PageBinder and one other"),"") -> 1 | T31: =IF(O31="PageBinder and a few others",COUNTIF(O$5:O31,"PageBinder and a few others"),"") | U31: =IF(O31="Most others, not PageBinder",COUNTIF(O$5:O31,"Most others, not PageBinder"),"") | V31: =IF(O31="All except PageBinder",COUNTIF(O$5:O31,"All except PageBinder"),"") | W31: =IF(O31="Shared by all",COUNTIF(O$5:O31,"Shared by all"),"")
A32: Pictures on the page | B32: Yes | C32: Yes | D32: Yes | E32: Yes | F32: Yes | G32: Yes | H32: Yes | I32: Yes | J32: Yes | K32: Yes | L32: Yes | M32: Yes | N32: =COUNTIF(B32:M32,"Yes*") -> 12 | O32: =IF(COUNTIF(B32:M32,"Yes*")=12,"Shared by all",IF(AND(LEFT(B32,3)="Yes",COUNTIF(B32:M32,"Yes*")=1),"Only PageBinder",IF(AND(LEFT(B32,3)="Yes",COUNTIF(B32:M32,"Yes*")=2),"PageBinder and one other",IF(AND(LEFT(B32,3)<>"Yes",COUNTIF(B32:M32,"Yes*")=11),"All except PageBinder",IF(AND(LEFT(B32,3)<>"Yes",COUNTIF(B32:M32,"Yes*")>=9),"Most others, not PageBinder",IF(AND(LEFT(B32,3)="Yes",COUNTIF(B32:M32,"Yes*")<=4),"PageBinder and a few others","")))))) -> Shared by all | P32: Shared by every program in the table. | Q32: Editing the page | R32: =IF(O32="Only PageBinder",COUNTIF(O$5:O32,"Only PageBinder"),"") | S32: =IF(O32="PageBinder and one other",COUNTIF(O$5:O32,"PageBinder and one other"),"") | T32: =IF(O32="PageBinder and a few others",COUNTIF(O$5:O32,"PageBinder and a few others"),"") | U32: =IF(O32="Most others, not PageBinder",COUNTIF(O$5:O32,"Most others, not PageBinder"),"") | V32: =IF(O32="All except PageBinder",COUNTIF(O$5:O32,"All except PageBinder"),"") | W32: =IF(O32="Shared by all",COUNTIF(O$5:O32,"Shared by all"),"") -> 3
A33: To-do checkboxes | B33: Yes | C33: Yes | D33: Yes | E33: Yes | F33: Yes | G33: Yes | H33: Yes | I33: Yes | J33: Yes | K33: Yes | L33: Yes | M33: No | N33: =COUNTIF(B33:M33,"Yes*") -> 11 | O33: =IF(COUNTIF(B33:M33,"Yes*")=12,"Shared by all",IF(AND(LEFT(B33,3)="Yes",COUNTIF(B33:M33,"Yes*")=1),"Only PageBinder",IF(AND(LEFT(B33,3)="Yes",COUNTIF(B33:M33,"Yes*")=2),"PageBinder and one other",IF(AND(LEFT(B33,3)<>"Yes",COUNTIF(B33:M33,"Yes*")=11),"All except PageBinder",IF(AND(LEFT(B33,3)<>"Yes",COUNTIF(B33:M33,"Yes*")>=9),"Most others, not PageBinder",IF(AND(LEFT(B33,3)="Yes",COUNTIF(B33:M33,"Yes*")<=4),"PageBinder and a few others","")))))) | Q33: Editing the page | R33: =IF(O33="Only PageBinder",COUNTIF(O$5:O33,"Only PageBinder"),"") | S33: =IF(O33="PageBinder and one other",COUNTIF(O$5:O33,"PageBinder and one other"),"") | T33: =IF(O33="PageBinder and a few others",COUNTIF(O$5:O33,"PageBinder and a few others"),"") | U33: =IF(O33="Most others, not PageBinder",COUNTIF(O$5:O33,"Most others, not PageBinder"),"") | V33: =IF(O33="All except PageBinder",COUNTIF(O$5:O33,"All except PageBinder"),"") | W33: =IF(O33="Shared by all",COUNTIF(O$5:O33,"Shared by all"),"")
A34: Shapes and drawing (lines, arrows, boxes) | B34: Yes: lines, arrows, rectangles, ellipses | C34: Partial: freehand drawing on mobile; plugin on desktop | D34: Partial: Canvas; Excalidraw plugin | E34: Yes: whiteboards | F34: Yes: canvas notes (Excalidraw) | G34: Plugin | H34: Yes: edgeless mode | I34: No | J34: No | K34: No | L34: Plugin | M34: Yes | N34: =COUNTIF(B34:M34,"Yes*") -> 5 | O34: =IF(COUNTIF(B34:M34,"Yes*")=12,"Shared by all",IF(AND(LEFT(B34,3)="Yes",COUNTIF(B34:M34,"Yes*")=1),"Only PageBinder",IF(AND(LEFT(B34,3)="Yes",COUNTIF(B34:M34,"Yes*")=2),"PageBinder and one other",IF(AND(LEFT(B34,3)<>"Yes",COUNTIF(B34:M34,"Yes*")=11),"All except PageBinder",IF(AND(LEFT(B34,3)<>"Yes",COUNTIF(B34:M34,"Yes*")>=9),"Most others, not PageBinder",IF(AND(LEFT(B34,3)="Yes",COUNTIF(B34:M34,"Yes*")<=4),"PageBinder and a few others","")))))) | Q34: Editing the page | R34: =IF(O34="Only PageBinder",COUNTIF(O$5:O34,"Only PageBinder"),"") | S34: =IF(O34="PageBinder and one other",COUNTIF(O$5:O34,"PageBinder and one other"),"") | T34: =IF(O34="PageBinder and a few others",COUNTIF(O$5:O34,"PageBinder and a few others"),"") | U34: =IF(O34="Most others, not PageBinder",COUNTIF(O$5:O34,"Most others, not PageBinder"),"") | V34: =IF(O34="All except PageBinder",COUNTIF(O$5:O34,"All except PageBinder"),"") | W34: =IF(O34="Shared by all",COUNTIF(O$5:O34,"Shared by all"),"")
A35: Handwriting with a stylus | B35: No | C35: Partial: mobile drawing | D35: Plugin | E35: Partial: whiteboards | F35: Yes: canvas notes | G35: No | H35: Yes: pen in edgeless mode | I35: No | J35: No | K35: No | L35: No | M35: Yes: pressure-sensitive pens, the core purpose | N35: =COUNTIF(B35:M35,"Yes*") -> 3 | O35: =IF(COUNTIF(B35:M35,"Yes*")=12,"Shared by all",IF(AND(LEFT(B35,3)="Yes",COUNTIF(B35:M35,"Yes*")=1),"Only PageBinder",IF(AND(LEFT(B35,3)="Yes",COUNTIF(B35:M35,"Yes*")=2),"PageBinder and one other",IF(AND(LEFT(B35,3)<>"Yes",COUNTIF(B35:M35,"Yes*")=11),"All except PageBinder",IF(AND(LEFT(B35,3)<>"Yes",COUNTIF(B35:M35,"Yes*")>=9),"Most others, not PageBinder",IF(AND(LEFT(B35,3)="Yes",COUNTIF(B35:M35,"Yes*")<=4),"PageBinder and a few others","")))))) | Q35: Editing the page | R35: =IF(O35="Only PageBinder",COUNTIF(O$5:O35,"Only PageBinder"),"") | S35: =IF(O35="PageBinder and one other",COUNTIF(O$5:O35,"PageBinder and one other"),"") | T35: =IF(O35="PageBinder and a few others",COUNTIF(O$5:O35,"PageBinder and a few others"),"") | U35: =IF(O35="Most others, not PageBinder",COUNTIF(O$5:O35,"Most others, not PageBinder"),"") | V35: =IF(O35="All except PageBinder",COUNTIF(O$5:O35,"All except PageBinder"),"") | W35: =IF(O35="Shared by all",COUNTIF(O$5:O35,"Shared by all"),"")
A36: Math formulas | B36: No | C36: Yes (KaTeX) | D36: Yes | E36: Yes | F36: Yes | G36: Yes | H36: Yes | I36: Yes | J36: Partial * | K36: Yes | L36: Plugin | M36: Yes (LaTeX tool) | N36: =COUNTIF(B36:M36,"Yes*") -> 9 | O36: =IF(COUNTIF(B36:M36,"Yes*")=12,"Shared by all",IF(AND(LEFT(B36,3)="Yes",COUNTIF(B36:M36,"Yes*")=1),"Only PageBinder",IF(AND(LEFT(B36,3)="Yes",COUNTIF(B36:M36,"Yes*")=2),"PageBinder and one other",IF(AND(LEFT(B36,3)<>"Yes",COUNTIF(B36:M36,"Yes*")=11),"All except PageBinder",IF(AND(LEFT(B36,3)<>"Yes",COUNTIF(B36:M36,"Yes*")>=9),"Most others, not PageBinder",IF(AND(LEFT(B36,3)="Yes",COUNTIF(B36:M36,"Yes*")<=4),"PageBinder and a few others","")))))) -> Most others, not PageBinder | Q36: Editing the page | R36: =IF(O36="Only PageBinder",COUNTIF(O$5:O36,"Only PageBinder"),"") | S36: =IF(O36="PageBinder and one other",COUNTIF(O$5:O36,"PageBinder and one other"),"") | T36: =IF(O36="PageBinder and a few others",COUNTIF(O$5:O36,"PageBinder and a few others"),"") | U36: =IF(O36="Most others, not PageBinder",COUNTIF(O$5:O36,"Most others, not PageBinder"),"") -> 2 | V36: =IF(O36="All except PageBinder",COUNTIF(O$5:O36,"All except PageBinder"),"") | W36: =IF(O36="Shared by all",COUNTIF(O$5:O36,"Shared by all"),"")
A37: Code blocks with highlighting | B37: No | C37: Yes | D37: Yes | E37: Yes | F37: Yes | G37: Yes | H37: Yes | I37: Yes | J37: Yes | K37: Yes | L37: Plugin | M37: No | N37: =COUNTIF(B37:M37,"Yes*") -> 9 | O37: =IF(COUNTIF(B37:M37,"Yes*")=12,"Shared by all",IF(AND(LEFT(B37,3)="Yes",COUNTIF(B37:M37,"Yes*")=1),"Only PageBinder",IF(AND(LEFT(B37,3)="Yes",COUNTIF(B37:M37,"Yes*")=2),"PageBinder and one other",IF(AND(LEFT(B37,3)<>"Yes",COUNTIF(B37:M37,"Yes*")=11),"All except PageBinder",IF(AND(LEFT(B37,3)<>"Yes",COUNTIF(B37:M37,"Yes*")>=9),"Most others, not PageBinder",IF(AND(LEFT(B37,3)="Yes",COUNTIF(B37:M37,"Yes*")<=4),"PageBinder and a few others","")))))) -> Most others, not PageBinder | Q37: Editing the page | R37: =IF(O37="Only PageBinder",COUNTIF(O$5:O37,"Only PageBinder"),"") | S37: =IF(O37="PageBinder and one other",COUNTIF(O$5:O37,"PageBinder and one other"),"") | T37: =IF(O37="PageBinder and a few others",COUNTIF(O$5:O37,"PageBinder and a few others"),"") | U37: =IF(O37="Most others, not PageBinder",COUNTIF(O$5:O37,"Most others, not PageBinder"),"") -> 3 | V37: =IF(O37="All except PageBinder",COUNTIF(O$5:O37,"All except PageBinder"),"") | W37: =IF(O37="Shared by all",COUNTIF(O$5:O37,"Shared by all"),"")
A38: Templates for new pages | B38: Yes: per notebook and global; edited in place as pages | C38: Plugin | D38: Yes | E38: Yes | F38: Yes | G38: Yes | H38: Yes | I38: Yes | J38: Yes | K38: No * | L38: Yes | M38: Yes (page templates) | N38: =COUNTIF(B38:M38,"Yes*") -> 10 | O38: =IF(COUNTIF(B38:M38,"Yes*")=12,"Shared by all",IF(AND(LEFT(B38,3)="Yes",COUNTIF(B38:M38,"Yes*")=1),"Only PageBinder",IF(AND(LEFT(B38,3)="Yes",COUNTIF(B38:M38,"Yes*")=2),"PageBinder and one other",IF(AND(LEFT(B38,3)<>"Yes",COUNTIF(B38:M38,"Yes*")=11),"All except PageBinder",IF(AND(LEFT(B38,3)<>"Yes",COUNTIF(B38:M38,"Yes*")>=9),"Most others, not PageBinder",IF(AND(LEFT(B38,3)="Yes",COUNTIF(B38:M38,"Yes*")<=4),"PageBinder and a few others","")))))) | Q38: Editing the page | R38: =IF(O38="Only PageBinder",COUNTIF(O$5:O38,"Only PageBinder"),"") | S38: =IF(O38="PageBinder and one other",COUNTIF(O$5:O38,"PageBinder and one other"),"") | T38: =IF(O38="PageBinder and a few others",COUNTIF(O$5:O38,"PageBinder and a few others"),"") | U38: =IF(O38="Most others, not PageBinder",COUNTIF(O$5:O38,"Most others, not PageBinder"),"") | V38: =IF(O38="All except PageBinder",COUNTIF(O$5:O38,"All except PageBinder"),"") | W38: =IF(O38="Shared by all",COUNTIF(O$5:O38,"Shared by all"),"")
A39: Saved emails show sender, subject, and date and are searchable | B39: Yes: .eml and .msg files | C39: No | D39: No | E39: No | F39: No | G39: No | H39: No | I39: No | J39: No | K39: No | L39: No | M39: No | N39: =COUNTIF(B39:M39,"Yes*") -> 1 | O39: =IF(COUNTIF(B39:M39,"Yes*")=12,"Shared by all",IF(AND(LEFT(B39,3)="Yes",COUNTIF(B39:M39,"Yes*")=1),"Only PageBinder",IF(AND(LEFT(B39,3)="Yes",COUNTIF(B39:M39,"Yes*")=2),"PageBinder and one other",IF(AND(LEFT(B39,3)<>"Yes",COUNTIF(B39:M39,"Yes*")=11),"All except PageBinder",IF(AND(LEFT(B39,3)<>"Yes",COUNTIF(B39:M39,"Yes*")>=9),"Most others, not PageBinder",IF(AND(LEFT(B39,3)="Yes",COUNTIF(B39:M39,"Yes*")<=4),"PageBinder and a few others","")))))) -> Only PageBinder | P39: An email dropped into the other programs is stored as an ordinary file. | Q39: Editing the page | R39: =IF(O39="Only PageBinder",COUNTIF(O$5:O39,"Only PageBinder"),"") -> 1 | S39: =IF(O39="PageBinder and one other",COUNTIF(O$5:O39,"PageBinder and one other"),"") | T39: =IF(O39="PageBinder and a few others",COUNTIF(O$5:O39,"PageBinder and a few others"),"") | U39: =IF(O39="Most others, not PageBinder",COUNTIF(O$5:O39,"Most others, not PageBinder"),"") | V39: =IF(O39="All except PageBinder",COUNTIF(O$5:O39,"All except PageBinder"),"") | W39: =IF(O39="Shared by all",COUNTIF(O$5:O39,"Shared by all"),"")
A40: Insert an attached PDF's pages as a printout on the page | B40: Yes | C40: No | D40: Partial: embedded PDF viewer | E40: Partial: PDF viewer for annotation | F40: Partial: PDF preview | G40: Partial: PDF viewer for annotation | H40: Partial: PDF embed * | I40: No | J40: No | K40: No | L40: No | M40: Yes: PDF as page background | N40: =COUNTIF(B40:M40,"Yes*") -> 2 | O40: =IF(COUNTIF(B40:M40,"Yes*")=12,"Shared by all",IF(AND(LEFT(B40,3)="Yes",COUNTIF(B40:M40,"Yes*")=1),"Only PageBinder",IF(AND(LEFT(B40,3)="Yes",COUNTIF(B40:M40,"Yes*")=2),"PageBinder and one other",IF(AND(LEFT(B40,3)<>"Yes",COUNTIF(B40:M40,"Yes*")=11),"All except PageBinder",IF(AND(LEFT(B40,3)<>"Yes",COUNTIF(B40:M40,"Yes*")>=9),"Most others, not PageBinder",IF(AND(LEFT(B40,3)="Yes",COUNTIF(B40:M40,"Yes*")<=4),"PageBinder and a few others","")))))) -> PageBinder and one other | Q40: Editing the page | R40: =IF(O40="Only PageBinder",COUNTIF(O$5:O40,"Only PageBinder"),"") | S40: =IF(O40="PageBinder and one other",COUNTIF(O$5:O40,"PageBinder and one other"),"") -> 2 | T40: =IF(O40="PageBinder and a few others",COUNTIF(O$5:O40,"PageBinder and a few others"),"") | U40: =IF(O40="Most others, not PageBinder",COUNTIF(O$5:O40,"Most others, not PageBinder"),"") | V40: =IF(O40="All except PageBinder",COUNTIF(O$5:O40,"All except PageBinder"),"") | W40: =IF(O40="Shared by all",COUNTIF(O$5:O40,"Shared by all"),"")
A41: Printing and export | Q41: Printing and export
...

Sheet Summary
A1: How to read the comparison
A3: The Comparison sheet has one row per feature and one column per program. PageBinder is the first column so its differences are easy to see, but every program is described the same way and none is scored.
A4: Green cells start with Yes, amber with Partial, Plugin, or Paid, red with No, grey with N/A or Not stated. The Pattern column reads the whole row: 'Only PageBinder' means no other program answers Yes; 'All except PageBinder' means PageBinder is the only one that does not; 'Shared by all' means everyone answers Yes.
A5: Use the filter on the Pattern column to see just the differences, or on the Category column to see one topic. The counts below are formulas over the Comparison sheet and update if a cell is changed.
A6: Pick by need, not by count: a program with fewer Yes answers may fit better. For example, someone who wants encrypted sync across phones has different needs from someone who wants printable records with large attachments on a NAS.
A8: Where the programs differ
A9: Features only PageBinder has | B9: =COUNTIF(Comparison!$O$5:$O$72,"Only PageBinder") -> 4
A10: Features PageBinder shares with just one other program | B10: =COUNTIF(Comparison!$O$5:$O$72,"PageBinder and one other") -> 5
A11: Features PageBinder has and a few others share | B11: =COUNTIF(Comparison!$O$5:$O$72,"PageBinder and a few others") -> 4
A12: Features every other program has and PageBinder lacks | B12: =COUNTIF(Comparison!$O$5:$O$72,"All except PageBinder") -> 0
A13: Features most other programs have and PageBinder lacks | B13: =COUNTIF(Comparison!$O$5:$O$72,"Most others, not PageBinder") -> 5
A14: Features shared by every program | B14: =COUNTIF(Comparison!$O$5:$O$72,"Shared by all") -> 3
A16: Yes answers by category (a count of rows answered Yes, not a score)
A17: Category | B17: PageBinder | C17: Joplin | D17: Obsidian | E17: Logseq | F17: Trilium Notes | G17: SiYuan | H17: AFFiNE | I17: AppFlowy | J17: Anytype | K17: Notesnook | L17: Zim Desktop Wiki | M17: Xournal++ | N17: Rows in category
A18: Basics | B18: =COUNTIFS(Comparison!$Q$5:$Q$72,$A18,Comparison!B$5:B$72,"Yes*") -> 2 | C18: =COUNTIFS(Comparison!$Q$5:$Q$72,$A18,Comparison!C$5:C$72,"Yes*") -> 3 | D18: =COUNTIFS(Comparison!$Q$5:$Q$72,$A18,Comparison!D$5:D$72,"Yes*") -> 3 | E18: =COUNTIFS(Comparison!$Q$5:$Q$72,$A18,Comparison!E$5:E$72,"Yes*") -> 3 | F18: =COUNTIFS(Comparison!$Q$5:$Q$72,$A18,Comparison!F$5:F$72,"Yes*") -> 2 | G18: =COUNTIFS(Comparison!$Q$5:$Q$72,$A18,Comparison!G$5:G$72,"Yes*") -> 3 | H18: =COUNTIFS(Comparison!$Q$5:$Q$72,$A18,Comparison!H$5:H$72,"Yes*") -> 3 | I18: =COUNTIFS(Comparison!$Q$5:$Q$72,$A18,Comparison!I$5:I$72,"Yes*") -> 3 | ... M18: =COUNTIFS(Comparison!$Q$5:$Q$72,$A18,Comparison!M$5:M$72,"Yes*") -> 2 | N18: =COUNTIF(Comparison!$Q$5:$Q$72,$A18)-1 -> 7
A19: Where your notes live | B19: =COUNTIFS(Comparison!$Q$5:$Q$72,$A19,Comparison!B$5:B$72,"Yes*") -> 6 | C19: =COUNTIFS(Comparison!$Q$5:$Q$72,$A19,Comparison!C$5:C$72,"Yes*") -> 2 | D19: =COUNTIFS(Comparison!$Q$5:$Q$72,$A19,Comparison!D$5:D$72,"Yes*") -> 6 | E19: =COUNTIFS(Comparison!$Q$5:$Q$72,$A19,Comparison!E$5:E$72,"Yes*") -> 5 | F19: =COUNTIFS(Comparison!$Q$5:$Q$72,$A19,Comparison!F$5:F$72,"Yes*") -> 1 | G19: =COUNTIFS(Comparison!$Q$5:$Q$72,$A19,Comparison!G$5:G$72,"Yes*") -> 5 | H19: =COUNTIFS(Comparison!$Q$5:$Q$72,$A19,Comparison!H$5:H$72,"Yes*") -> 1 | I19: =COUNTIFS(Comparison!$Q$5:$Q$72,$A19,Comparison!I$5:I$72,"Yes*") -> 1 | ... M19: =COUNTIFS(Comparison!$Q$5:$Q$72,$A19,Comparison!M$5:M$72,"Yes*") -> 2 | N19: =COUNTIF(Comparison!$Q$5:$Q$72,$A19)-1 -> 7
A20: Organising | B20: =COUNTIFS(Comparison!$Q$5:$Q$72,$A20,Comparison!B$5:B$72,"Yes*") -> 0 | C20: =COUNTIFS(Comparison!$Q$5:$Q$72,$A20,Comparison!C$5:C$72,"Yes*") -> 1 | D20: =COUNTIFS(Comparison!$Q$5:$Q$72,$A20,Comparison!D$5:D$72,"Yes*") -> 3 | E20: =COUNTIFS(Comparison!$Q$5:$Q$72,$A20,Comparison!E$5:E$72,"Yes*") -> 4 | F20: =COUNTIFS(Comparison!$Q$5:$Q$72,$A20,Comparison!F$5:F$72,"Yes*") -> 3 | G20: =COUNTIFS(Comparison!$Q$5:$Q$72,$A20,Comparison!G$5:G$72,"Yes*") -> 4 | H20: =COUNTIFS(Comparison!$Q$5:$Q$72,$A20,Comparison!H$5:H$72,"Yes*") -> 2 | I20: =COUNTIFS(Comparison!$Q$5:$Q$72,$A20,Comparison!I$5:I$72,"Yes*") -> 0 | ... M20: =COUNTIFS(Comparison!$Q$5:$Q$72,$A20,Comparison!M$5:M$72,"Yes*") -> 0 | N20: =COUNTIF(Comparison!$Q$5:$Q$72,$A20)-1 -> 5
A21: Editing the page | B21: =COUNTIFS(Comparison!$Q$5:$Q$72,$A21,Comparison!B$5:B$72,"Yes*") -> 9 | C21: =COUNTIFS(Comparison!$Q$5:$Q$72,$A21,Comparison!C$5:C$72,"Yes*") -> 5 | D21: =COUNTIFS(Comparison!$Q$5:$Q$72,$A21,Comparison!D$5:D$72,"Yes*") -> 6 | E21: =COUNTIFS(Comparison!$Q$5:$Q$72,$A21,Comparison!E$5:E$72,"Yes*") -> 6 | F21: =COUNTIFS(Comparison!$Q$5:$Q$72,$A21,Comparison!F$5:F$72,"Yes*") -> 9 | G21: =COUNTIFS(Comparison!$Q$5:$Q$72,$A21,Comparison!G$5:G$72,"Yes*") -> 6 | H21: =COUNTIFS(Comparison!$Q$5:$Q$72,$A21,Comparison!H$5:H$72,"Yes*") -> 9 | I21: =COUNTIFS(Comparison!$Q$5:$Q$72,$A21,Comparison!I$5:I$72,"Yes*") -> 6 | ... M21: =COUNTIFS(Comparison!$Q$5:$Q$72,$A21,Comparison!M$5:M$72,"Yes*") -> 7 | N21: =COUNTIF(Comparison!$Q$5:$Q$72,$A21)-1 -> 13
A22: Printing and export | B22: =COUNTIFS(Comparison!$Q$5:$Q$72,$A22,Comparison!B$5:B$72,"Yes*") -> 6 | C22: =COUNTIFS(Comparison!$Q$5:$Q$72,$A22,Comparison!C$5:C$72,"Yes*") -> 3 | D22: =COUNTIFS(Comparison!$Q$5:$Q$72,$A22,Comparison!D$5:D$72,"Yes*") -> 2 | E22: =COUNTIFS(Comparison!$Q$5:$Q$72,$A22,Comparison!E$5:E$72,"Yes*") -> 2 | F22: =COUNTIFS(Comparison!$Q$5:$Q$72,$A22,Comparison!F$5:F$72,"Yes*") -> 3 | G22: =COUNTIFS(Comparison!$Q$5:$Q$72,$A22,Comparison!G$5:G$72,"Yes*") -> 3 | H22: =COUNTIFS(Comparison!$Q$5:$Q$72,$A22,Comparison!H$5:H$72,"Yes*") -> 3 | I22: =COUNTIFS(Comparison!$Q$5:$Q$72,$A22,Comparison!I$5:I$72,"Yes*") -> 1 | ... M22: =COUNTIFS(Comparison!$Q$5:$Q$72,$A22,Comparison!M$5:M$72,"Yes*") -> 4 | N22: =COUNTIF(Comparison!$Q$5:$Q$72,$A22)-1 -> 7
A23: Search | B23: =COUNTIFS(Comparison!$Q$5:$Q$72,$A23,Comparison!B$5:B$72,"Yes*") -> 3 | C23: =COUNTIFS(Comparison!$Q$5:$Q$72,$A23,Comparison!C$5:C$72,"Yes*") -> 3 | D23: =COUNTIFS(Comparison!$Q$5:$Q$72,$A23,Comparison!D$5:D$72,"Yes*") -> 2 | E23: =COUNTIFS(Comparison!$Q$5:$Q$72,$A23,Comparison!E$5:E$72,"Yes*") -> 2 | F23: =COUNTIFS(Comparison!$Q$5:$Q$72,$A23,Comparison!F$5:F$72,"Yes*") -> 3 | G23: =COUNTIFS(Comparison!$Q$5:$Q$72,$A23,Comparison!G$5:G$72,"Yes*") -> 3 | H23: =COUNTIFS(Comparison!$Q$5:$Q$72,$A23,Comparison!H$5:H$72,"Yes*") -> 2 | I23: =COUNTIFS(Comparison!$Q$5:$Q$72,$A23,Comparison!I$5:I$72,"Yes*") -> 2 | ... M23: =COUNTIFS(Comparison!$Q$5:$Q$72,$A23,Comparison!M$5:M$72,"Yes*") -> 0 | N23: =COUNTIF(Comparison!$Q$5:$Q$72,$A23)-1 -> 4
A24: Keeping notes safe | B24: =COUNTIFS(Comparison!$Q$5:$Q$72,$A24,Comparison!B$5:B$72,"Yes*") -> 5 | C24: =COUNTIFS(Comparison!$Q$5:$Q$72,$A24,Comparison!C$5:C$72,"Yes*") -> 3 | D24: =COUNTIFS(Comparison!$Q$5:$Q$72,$A24,Comparison!D$5:D$72,"Yes*") -> 1 | E24: =COUNTIFS(Comparison!$Q$5:$Q$72,$A24,Comparison!E$5:E$72,"Yes*") -> 2 | F24: =COUNTIFS(Comparison!$Q$5:$Q$72,$A24,Comparison!F$5:F$72,"Yes*") -> 2 | G24: =COUNTIFS(Comparison!$Q$5:$Q$72,$A24,Comparison!G$5:G$72,"Yes*") -> 3 | H24: =COUNTIFS(Comparison!$Q$5:$Q$72,$A24,Comparison!H$5:H$72,"Yes*") -> 2 | I24: =COUNTIFS(Comparison!$Q$5:$Q$72,$A24,Comparison!I$5:I$72,"Yes*") -> 2 | ... M24: =COUNTIFS(Comparison!$Q$5:$Q$72,$A24,Comparison!M$5:M$72,"Yes*") -> 0 | N24: =COUNTIF(Comparison!$Q$5:$Q$72,$A24)-1 -> 5
